Workbook
Name Slicer_Diabetes_Status: #N/A
Name Slicer_Weight_Status: #N/A

Sheet Customer Names
A1: Customer ID | B1: Title | C1: First Name | D1: Last Name
A2: Id1 | B2: Ms. | C2: Kelly | D2: Hawks
A3: Id2 | B3: Mr. | C3: Matthew D | D3: Lehner
A4: Id3 | B4: Mr. | C4: Phil | D4: Lu
A5: Id4 | B5: Ms. | C5: Kelsey | D5: Osborne
A6: Id5 | B6: Ms. | C6: Kristyn | D6: Kadala
A7: Id6 | B7: Mr. | C7: Russell B. | D7: Baker
A8: Id7 | B8: Mr. | C8: Scott | D8: Macpherson
A9: Id8 | B9: Mr. | C9: Stephen | D9: Hallman
A10: Id9 | B10: Mr. | C10: Patrick R. | D10: Moran
A11: Id10 | B11: Ms. | C11: Brooke N. | D11: Benner
A12: Id11 | B12: Ms. | C12: Paola Andrea | D12: Fierro Vargas
... A2336: Id2335 | B2336: Mr. | C2336: Aaron K | D2336: German

Sheet Medical Examinations
A1: Customer ID | B1: BMI | C1: HBA1C | D1: Heart Issues | E1: Any Transplants | F1: Cancer history | G1: NumberOfMajorSurgeries | H1: smoker | I1: Weight Status | J1: Diabetes Status
A2: Id1 | B2: 47.41 | C2: 7.47 | D2: No | E2: No | F2: No | G2: 0 | H2: yes | I2: =IF(B2<18.5,"Underweight",IF(B2<25,"Normal Weight",IF(B2<30,"Overweight","Obesity"))) -> Obesity | J2: =IF(ISNUMBER(C2),IF(C2<5.7,"Normal",IF(C2<6.5,"Prediabetes","Diabetes")),"") -> Diabetes
A3: Id2 | B3: 30.36 | C3: 5.77 | D3: No | E3: No | F3: No | G3: 0 | H3: yes | I3: =IF(B3<18.5,"Underweight",IF(B3<25,"Normal Weight",IF(B3<30,"Overweight","Obesity"))) -> Obesity | J3: =IF(ISNUMBER(C3),IF(C3<5.7,"Normal",IF(C3<6.5,"Prediabetes","Diabetes")),"") -> Prediabetes
A4: Id3 | B4: 34.485 | C4: 11.87 | D4: yes | E4: No | F4: No | G4: 2 | H4: yes | I4: =IF(B4<18.5,"Underweight",IF(B4<25,"Normal Weight",IF(B4<30,"Overweight","Obesity"))) -> Obesity | J4: =IF(ISNUMBER(C4),IF(C4<5.7,"Normal",IF(C4<6.5,"Prediabetes","Diabetes")),"") -> Diabetes
A5: Id4 | B5: 38.095 | C5: 6.05 | D5: No | E5: No | F5: No | G5: 0 | H5: yes | I5: =IF(B5<18.5,"Underweight",IF(B5<25,"Normal Weight",IF(B5<30,"Overweight","Obesity"))) -> Obesity | J5: =IF(ISNUMBER(C5),IF(C5<5.7,"Normal",IF(C5<6.5,"Prediabetes","Diabetes")),"") -> Prediabetes
A6: Id5 | B6: 35.53 | C6: 5.45 | D6: No | E6: No | F6: No | G6: 0 | H6: yes | I6: =IF(B6<18.5,"Underweight",IF(B6<25,"Normal Weight",IF(B6<30,"Overweight","Obesity"))) -> Obesity | J6: =IF(ISNUMBER(C6),IF(C6<5.7,"Normal",IF(C6<6.5,"Prediabetes","Diabetes")),"") -> Normal
A7: Id6 | B7: 32.8 | C7: 6.59 | D7: No | E7: No | F7: No | G7: 0 | H7: yes | I7: =IF(B7<18.5,"Underweight",IF(B7<25,"Normal Weight",IF(B7<30,"Overweight","Obesity"))) -> Obesity | J7: =IF(ISNUMBER(C7),IF(C7<5.7,"Normal",IF(C7<6.5,"Prediabetes","Diabetes")),"") -> Diabetes
A8: Id7 | B8: 36.4 | C8: 6.07 | D8: No | E8: No | F8: No | G8: 0 | H8: yes | I8: =IF(B8<18.5,"Underweight",IF(B8<25,"Normal Weight",IF(B8<30,"Overweight","Obesity"))) -> Obesity | J8: =IF(ISNUMBER(C8),IF(C8<5.7,"Normal",IF(C8<6.5,"Prediabetes","Diabetes")),"") -> Prediabetes
A9: Id8 | B9: 36.96 | C9: 7.93 | D9: No | E9: No | F9: No | G9: 3 | H9: yes | I9: =IF(B9<18.5,"Underweight",IF(B9<25,"Normal Weight",IF(B9<30,"Overweight","Obesity"))) -> Obesity | J9: =IF(ISNUMBER(C9),IF(C9<5.7,"Normal",IF(C9<6.5,"Prediabetes","Diabetes")),"") -> Diabetes
A10: Id9 | B10: 41.14 | C10: 9.58 | D10: yes | E10: No | F10: Yes | G10: 1 | H10: yes | I10: =IF(B10<18.5,"Underweight",IF(B10<25,"Normal Weight",IF(B10<30,"Overweight","Obesity"))) -> Obesity | J10: =IF(ISNUMBER(C10),IF(C10<5.7,"Normal",IF(C10<6.5,"Prediabetes","Diabetes")),"") -> Diabetes
A11: Id10 | B11: 38.06 | C11: 10.79 | D11: No | E11: No | F11: No | G11: 0 | H11: yes | I11: =IF(B11<18.5,"Underweight",IF(B11<25,"Normal Weight",IF(B11<30,"Overweight","Obesity"))) -> Obesity | J11: =IF(ISNUMBER(C11),IF(C11<5.7,"Normal",IF(C11<6.5,"Prediabetes","Diabetes")),"") -> Diabetes
A12: Id11 | B12: 37.7 | C12: 5.96 | D12: yes | E12: No | F12: No | G12: 2 | H12: yes | I12: =IF(B12<18.5,"Underweight",IF(B12<25,"Normal Weight",IF(B12<30,"Overweight","Obesity"))) -> Obesity | J12: =IF(ISNUMBER(C12),IF(C12<5.7,"Normal",IF(C12<6.5,"Prediabetes","Diabetes")),"") -> Prediabetes
A13: Id12 | B13: 42.13 | C13: 11.9 | D13: No | E13: No | F13: No | G13: 0 | H13: yes | I13: =IF(B13<18.5,"Underweight",IF(B13<25,"Normal Weight",IF(B13<30,"Overweight","Obesity"))) -> Obesity | J13: =IF(ISNUMBER(C13),IF(C13<5.7,"Normal",IF(C13<6.5,"Prediabetes","Diabetes")),"") -> Diabetes
... A2336: Id2335 | B2336: 17.58 | C2336: 4.51 | D2336: No | E2336: No | F2336: No | G2336: 1 | H2336: No | I2336: =IF(B2336<18.5,"Underweight",IF(B2336<25,"Normal Weight",IF(B2336<30,"Overweight","Obesity"))) -> Underweight | J2336: =IF(ISNUMBER(C2336),IF(C2336<5.7,"Normal",IF(C2336<6.5,"Prediabetes","Diabetes")),"") -> Normal

Sheet Hospitalisation Details
A1: Customer ID | B1: Date of Birth | C1: children | D1: charges | E1: Hospital tier | F1: City tier | G1: State ID | H1: Age
A2: Id2335 | B2: 33794 | C2: 0 | D2: 563.84 | E2: tier - 2 | F2: tier - 3 | G2: R1013 | H2: =IFERROR(DATEDIF(B2,DATE(2023,6,8),"Y"),"?") -> 30
A3: Id2334 | B3: 33938 | C3: 0 | D3: 570.62 | E3: tier - 2 | F3: tier - 1 | G3: R1013 | H3: =IFERROR(DATEDIF(B3,DATE(2023,6,8),"Y"),"?") -> 30
A4: Id2333 | B4: 34150 | C4: 0 | D4: 600 | E4: tier - 2 | F4: tier - 1 | G4: R1013 | H4: =IFERROR(DATEDIF(B4,DATE(2023,6,8),"Y"),"?") -> 29
A5: Id2332 | B5: 33860 | C5: 0 | D5: 604.54 | E5: tier - 3 | F5: tier - 3 | G5: R1013 | H5: =IFERROR(DATEDIF(B5,DATE(2023,6,8),"Y"),"?") -> 30
A6: Id2331 | B6: 36003 | C6: 0 | D6: 637.26 | E6: tier - 3 | F6: tier - 3 | G6: R1013 | H6: =IFERROR(DATEDIF(B6,DATE(2023,6,8),"Y"),"?") -> 24
A7: Id2330 | B7: 37215 | C7: 0 | D7: 646.14 | E7: tier - 3 | F7: tier - 3 | G7: R1012 | H7: =IFERROR(DATEDIF(B7,DATE(2023,6,8),"Y"),"?") -> 21
A8: Id2329 | B8: 34121 | C8: 0 | D8: 650 | E8: tier - 3 | F8: tier - 3 | G8: R1013 | H8: =IFERROR(DATEDIF(B8,DATE(2023,6,8),"Y"),"?") -> 30
A9: Id2328 | B9: 34884 | C9: 0 | D9: 650 | E9: tier - 3 | F9: tier - 3 | G9: R1013 | H9: =IFERROR(DATEDIF(B9,DATE(2023,6,8),"Y"),"?") -> 27
A10: Id2327 | B10: 37589 | C10: 0 | D10: 668 | E10: tier - 3 | F10: tier - 2 | G10: R1012 | H10: =IFERROR(DATEDIF(B10,DATE(2023,6,8),"Y"),"?") -> 20
A11: Id2326 | B11: 35743 | C11: 0 | D11: 670 | E11: tier - 3 | F11: tier - 3 | G11: R1013 | H11: =IFERROR(DATEDIF(B11,DATE(2023,6,8),"Y"),"?") -> 25
A12: Id2325 | B12: 37146 | C12: 0 | D12: 687.54 | E12: tier - 3 | F12: tier - 2 | G12: R1013 | H12: =IFERROR(DATEDIF(B12,DATE(2023,6,8),"Y"),"?") -> 21
A13: Id2324 | B13: 36520 | C13: 0 | D13: 700 | E13: ? | F13: tier - 3 | G13: R1013 | H13: =IFERROR(DATEDIF(B13,DATE(2023,6,8),"Y"),"?") -> 23
... A1050: Id1290 | B1050: 28332 | C1050: 2 | D1050: 8527.53 | E1050: tier - 2 | F1050: tier - 2 | G1050: R1013 | H1050: =IFERROR(DATEDIF(B1050,DATE(2023,6,8),"Y"),"?") -> 45
A1051: Id1289 | B1051: ? | C1051: 0 | D1051: 8534.67 | E1051: tier - 2 | F1051: tier - 3 | G1051: R1024 | H1051: =IFERROR(DATEDIF(B1051,DATE(2023,6,8),"Y"),"?") -> ?
A1052: Id1288 | B1052: 29947 | C1052: 3 | D1052: 8538.29 | E1052: tier - 2 | F1052: tier - 3 | G1052: R1024 | H1052: =IFERROR(DATEDIF(B1052,DATE(2023,6,8),"Y"),"?") -> 41
A1053: Id1287 | B1053: 27704 | C1053: 1 | D1053: 8539.67 | E1053: tier - 2 | F1053: tier - 3 | G1053: R1011 | H1053: =IFERROR(DATEDIF(B1053,DATE(2023,6,8),"Y"),"?") -> 47
A1054: Id1286 | B1054: ? | C1054: 1 | D1054: 8547.69 | E1054: tier - 2 | F1054: tier - 1 | G1054: R1013 | H1054: =IFERROR(DATEDIF(B1054,DATE(2023,6,8),"Y"),"?") -> ?
A1055: Id1285 | B1055: 27612 | C1055: 1 | D1055: 8551.35 | E1055: tier - 2 | F1055: tier - 2 | G1055: R1011 | H1055: =IFERROR(DATEDIF(B1055,DATE(2023,6,8),"Y"),"?") -> 47
A1056: Id1284 | B1056: 27627 | C1056: 1 | D1056: 8556.91 | E1056: tier - 2 | F1056: tier - 1 | G1056: R1011 | H1056: =IFERROR(DATEDIF(B1056,DATE(2023,6,8),"Y"),"?") -> 47
A1057: Id1283 | B1057: 32407 | C1057: 3 | D1057: 8567.25 | E1057: tier - 2 | F1057: tier - 1 | G1057: R1012 | H1057: =IFERROR(DATEDIF(B1057,DATE(2023,6,8),"Y"),"?") -> 34
A1058: Id1282 | B1058: 27663 | C1058: 1 | D1058: 8569.86 | E1058: tier - 2 | F1058: tier - 3 | G1058: R1013 | H1058: =IFERROR(DATEDIF(B1058,DATE(2023,6,8),"Y"),"?") -> 47
A1059: Id1281 | B1059: 30291 | C1059: 3 | D1059: 8572.04 | E1059: tier - 2 | F1059: tier - 2 | G1059: R1021 | H1059: =IFERROR(DATEDIF(B1059,DATE(2023,6,8),"Y"),"?") -> 40
A1060: Id1280 | B1060: 32092 | C1060: 3 | D1060: 8573.3 | E1060: tier - 2 | F1060: tier - 2 | G1060: R1021 | H1060: =IFERROR(DATEDIF(B1060,DATE(2023,6,8),"Y"),"?") -> 35
A1061: Id1279 | B1061: 30680 | C1061: 5 | D1061: 8582.3 | E1061: tier - 2 | F1061: tier - 1 | G1061: R1013 | H1061: =IFERROR(DATEDIF(B1061,DATE(2023,6,8),"Y"),"?") -> 39
A1062: Id1278 | B1062: 30522 | C1062: 5 | D1062: 8596.83 | E1062: tier - 2 | F1062: tier - 3 | G1062: R1013 | H1062: =IFERROR(DATEDIF(B1062,DATE(2023,6,8),"Y"),"?") -> 39
A1063: Id1277 | B1063: 26856 | C1063: 0 | D1063: 8601.33 | E1063: tier - 2 | F1063: tier - 1 | G1063: R1013 | H1063: =IFERROR(DATEDIF(B1063,DATE(2023,6,8),"Y"),"?") -> 49
A1064: Id1276 | B1064: 28392 | C1064: 2 | D1064: 8603.82 | E1064: tier - 2 | F1064: tier - 1 | G1064: R1019 | H1064: =IFERROR(DATEDIF(B1064,DATE(2023,6,8),"Y"),"?") -> 45
A1065: Id1275 | B1065: 28441 | C1065: 2 | D1065: 8604.48 | E1065: tier - 3 | F1065: tier - 2 | G1065: R1016 | H1065: =IFERROR(DATEDIF(B1065,DATE(2023,6,8),"Y"),"?") -> 45
A1066: Id1274 | B1066: 28413 | C1066: 3 | D1066: 8605.36 | E1066: tier - 2 | F1066: tier - 2 | G1066: R1013 | H1066: =IFERROR(DATEDIF(B1066,DATE(2023,6,8),"Y"),"?") -> 45
... A2344: Id1 | B2344: 25123 | C2344: 0 | D2344: 63770.43 | E2344: tier - 1 | F2344: tier - 3 | G2344: R1013 | H2344: =IFERROR(DATEDIF(B2344,DATE(2023,6,8),"Y"),"?") -> 54
B2345: 29920 | E2345: tier - 2 | F2345: tier - 2 | H2345: =IFERROR(DATEDIF(B2345,DATE(2023,6,8),"Y"),"?") -> 41

Sheet Result
B1: Data Cleaning: (5 marks)
A2: 1 | B2: Check for the number of missing values marked with '?' in each column of the “Medical
B3: Examinations” Table and "Hospitalization Details" Table.
B4: Medical Examinations
B5: Customer ID | C5: BMI | D5: HBA1C | E5: Heart Issues | F5: Any Transplants | G5: Cancer history | H5: NumberOfMajorSurgeries | I5: smoker
B6: Id560 | C6: 23.98 | D6: 4.9 | E6: No | F6: No | G6: No | H6: No major surgery | I6: ?
B7: Id635 | C7: 25.175 | D7: 4.96 | E7: No | F7: yes | G7: No | H7: 1 | I7: ?
B8: Hospitalisation Details
B9: Customer ID | C9: year | D9: month | E9: date | F9: children | G9: charges | H9: Hospital tier | I9: City tier | J9: State ID
B10: ? | C10: 2004 | D10: Nov | E10: 6 | F10: 0 | G10: 1137.01 | H10: tier - 3 | I10: tier - 1 | J10: R1013
B11: ? | C11: 1999 | D11: Jun | E11: 9 | F11: 1 | G11: 2775.19 | H11: tier - 2 | I11: tier - 1 | J11: R1012
B12: ? | C12: 1985 | D12: Dec | E12: 20 | F12: 2 | G12: 6203.9 | H12: tier - 1 | I12: tier - 2 | J12: R1012
B13: ? | C13: 2000 | D13: Oct | E13: 13 | F13: 0 | G13: 35585.58 | H13: tier - 1 | I13: tier - 2 | J13: R1011
B14: ? | C14: 1992 | D14: Oct | E14: 6 | F14: 0 | G14: 36837.47 | H14: tier - 1 | I14: tier - 2 | J14: R1011
B15: ? | C15: 1991 | D15: Nov | E15: 22 | F15: 2 | G15: 38711 | H15: tier - 1 | I15: tier - 3 | J15: R1011
B16: Id2322 | C16: 2002 | D16: ? | E16: 19 | F16: 0 | G16: 750 | H16: tier - 3 | I16: tier - 1 | J16: R1012
B17: Id2318 | C17: 1996 | D17: ? | E17: 18 | F17: 0 | G17: 770.38 | H17: tier - 3 | I17: ? | J17: R1012
B18: Id3 | C18: 1970 | D18: ? | E18: 11 | F18: 3 | G18: 60021.4 | H18: tier - 1 | I18: tier - 1 | J18: R1012
B19: Id2324 | C19: 1999 | D19: Dec | E19: 26 | F19: 0 | G19: 700 | H19: ? | I19: tier - 3 | J19: R1013
B20: Id2318 | C20: 1996 | D20: ? | E20: 18 | F20: 0 | G20: 770.38 | H20: tier - 3 | I20: ? | J20: R1012
B21: Id1793 | C21: 1995 | D21: Dec | E21: 1 | F21: 3 | G21: 4827.9 | H21: tier - 1 | I21: tier - 2 | J21: Unknown
B22: Id170 | C22: 2000 | D22: Sep | E22: 5 | F22: 1 | G22: 37165.16 | H22: tier - 1 | I22: tier - 3 | J22: Unknown
A23: 2 | B23: Fill in the missing values of ‘month’ with Sep and ‘year’ with its average rounded to the
B24: nearest integer.
B25: Id1289 | C25: ? | D25: Jul | E25: 24 | F25: 0 | G25: 8534.67 | H25: tier - 2 | I25: tier - 3 | J25: R1024
B26: Id1286 | C26: ? | D26: Dec | E26: 12 | F26: 1 | G26: 8547.69 | H26: tier - 2 | I26: tier - 1 | J26: R1013
C27: 1983
B28: Id2322 | C28: 2002 | D28: ? | E28: 19 | F28: 0 | G28: 750 | H28: tier - 3 | I28: tier - 1 | J28: R1012
B29: Id2318 | C29: 1996 | D29: ? | E29: 18 | F29: 0 | G29: 770.38 | H29: tier - 3 | I29: ? | J29: R1012
B30: Id3 | C30: 1970 | D30: ? | E30: 11 | F30: 3 | G30: 60021.4 | H30: tier - 1 | I30: tier - 1 | J30: R1012
A31: 3 | B31: Determine the most frequently occurring values in the ‘smoker’, 'Hospital tier' and 'City
B32: tier' columns, and fill in the missing values accordingly.
B33: Id560 | C33: 23.98 | D33: 4.9 | E33: No | F33: No | G33: No | H33: No major surgery | I33: ?
B34: Id635 | C34: 25.175 | D34: 4.96 | E34: No | F34: yes | G34: No | H34: 1 | I34: ?
B35: Id2324 | C35: 1999 | D35: Dec | E35: 26 | F35: 0 | G35: 700 | H35: ? | I35: tier - 3 | J35: R1013
B36: Id2318 | C36: 1996 | D36: ? | E36: 18 | F36: 0 | G36: 770.38 | H36: tier - 3 | I36: ? | J36: R1012
A37: 4 | B37: If any 'State ID' values are missing, consider filling them with 'Unknown' or using another
B38: appropriate strategy.
B39: Id1793 | C39: 1995 | D39: Dec | E39: 1 | F39: 3 | G39: 4827.9 | H39: tier - 1 | I39: tier - 2 | J39: Unknown
B40: Id170 | C40: 2000 | D40: Sep | E40: 5 | F40: 1 | G40: 37165.16 | H40: tier - 1 | I40: tier - 3 | J40: Unknown
...

Sheet Healthcare
A1: Customer ID | B1: First Name | C1: BMI | D1: HBA1C | E1: Heart Issues | F1: Any Transplants | G1: Cancer history | H1: NumberOfMajorSurgeries | I1: smoker | J1: Weight Status | K1: Diabetes Status | L1: Date of Birth | M1: charges | N1: Hospital tier | O1: City tier | P1: State ID | Q1: Age
A2: ='Customer Names'!A2 -> Id1 | B2: =VLOOKUP($A2,'Customer Names'!$A$2:$D$2336,3,FALSE) -> Kelly | C2: =VLOOKUP($A2,'Medical Examinations'!$A$2:$J$2336,2,FALSE) -> 47.41 | D2: =VLOOKUP($A2,'Medical Examinations'!$A$2:$J$2336,3,FALSE) -> 7.47 | E2: =VLOOKUP($A2,'Medical Examinations'!$A$2:$J$2336,4,FALSE) -> No | F2: =VLOOKUP($A2,'Medical Examinations'!$A$2:$J$2336,5,FALSE) -> No | G2: =VLOOKUP($A2,'Medical Examinations'!$A$2:$J$2336,6,FALSE) -> No | H2: =VLOOKUP($A2,'Medical Examinations'!$A$2:$J$2336,7,FALSE) -> 0 | I2: =VLOOKUP($A2,'Medical Examinations'!$A$2:$J$2336,8,FALSE) -> yes | J2: =VLOOKUP($A2,'Medical Examinations'!$A$2:$J$2336,9,FALSE) -> Obesity | K2: =VLOOKUP($A2,'Medical Examinations'!$A$2:$J$2336,10,FALSE) -> Diabetes | L2: =VLOOKUP($A2,'Hospitalisation Details'!$A$2:$H$2345,2,FALSE) -> 25123 | M2: =VLOOKUP($A2,'Hospitalisation Details'!$A$2:$H$2345,4,FALSE) -> 63770.43 | N2: =VLOOKUP($A2,'Hospitalisation Details'!$A$2:$H$2345,5,FALSE) -> tier - 1 | O2: =VLOOKUP($A2,'Hospitalisation Details'!$A$2:$H$2345,6,FALSE) -> tier - 3 | P2: =VLOOKUP($A2,'Hospitalisation Details'!$A$2:$H$2345,7,FALSE) -> R1013 | Q2: =VLOOKUP($A2,'Hospitalisation Details'!$A$2:$H$2345,8,FALSE) -> 54
A3: ='Customer Names'!A3 -> Id2 | B3: =VLOOKUP($A3,'Customer Names'!$A$2:$D$2336,3,FALSE) -> Matthew D | C3: =VLOOKUP($A3,'Medical Examinations'!$A$2:$J$2336,2,FALSE) -> 30.36 | D3: =VLOOKUP($A3,'Medical Examinations'!$A$2:$J$2336,3,FALSE) -> 5.77 | E3: =VLOOKUP($A3,'Medical Examinations'!$A$2:$J$2336,4,FALSE) -> No | F3: =VLOOKUP($A3,'Medical Examinations'!$A$2:$J$2336,5,FALSE) -> No | G3: =VLOOKUP($A3,'Medical Examinations'!$A$2:$J$2336,6,FALSE) -> No | H3: =VLOOKUP($A3,'Medical Examinations'!$A$2:$J$2336,7,FALSE) -> 0 | I3: =VLOOKUP($A3,'Medical Examinations'!$A$2:$J$2336,8,FALSE) -> yes | J3: =VLOOKUP($A3,'Medical Examinations'!$A$2:$J$2336,9,FALSE) -> Obesity | K3: =VLOOKUP($A3,'Medical Examinations'!$A$2:$J$2336,10,FALSE) -> Prediabetes | L3: =VLOOKUP($A3,'Hospitalisation Details'!$A$2:$H$2345,2,FALSE) -> 28284 | M3: =VLOOKUP($A3,'Hospitalisation Details'!$A$2:$H$2345,4,FALSE) -> 62592.87 | N3: =VLOOKUP($A3,'Hospitalisation Details'!$A$2:$H$2345,5,FALSE) -> tier - 2 | O3: =VLOOKUP($A3,'Hospitalisation Details'!$A$2:$H$2345,6,FALSE) -> tier - 3 | P3: =VLOOKUP($A3,'Hospitalisation Details'!$A$2:$H$2345,7,FALSE) -> R1013 | Q3: =VLOOKUP($A3,'Hospitalisation Details'!$A$2:$H$2345,8,FALSE) -> 46
A4: ='Customer Names'!A4 -> Id3 | B4: =VLOOKUP($A4,'Customer Names'!$A$2:$D$2336,3,FALSE) -> Phil | C4: =VLOOKUP($A4,'Medical Examinations'!$A$2:$J$2336,2,FALSE) -> 34.485 | D4: =VLOOKUP($A4,'Medical Examinations'!$A$2:$J$2336,3,FALSE) -> 11.87 | E4: =VLOOKUP($A4,'Medical Examinations'!$A$2:$J$2336,4,FALSE) -> yes | F4: =VLOOKUP($A4,'Medical Examinations'!$A$2:$J$2336,5,FALSE) -> No | G4: =VLOOKUP($A4,'Medical Examinations'!$A$2:$J$2336,6,FALSE) -> No | H4: =VLOOKUP($A4,'Medical Examinations'!$A$2:$J$2336,7,FALSE) -> 2 | I4: =VLOOKUP($A4,'Medical Examinations'!$A$2:$J$2336,8,FALSE) -> yes | J4: =VLOOKUP($A4,'Medical Examinations'!$A$2:$J$2336,9,FALSE) -> Obesity | K4: =VLOOKUP($A4,'Medical Examinations'!$A$2:$J$2336,10,FALSE) -> Diabetes | L4: =VLOOKUP($A4,'Hospitalisation Details'!$A$2:$H$2345,2,FALSE) -> 1970 | M4: =VLOOKUP($A4,'Hospitalisation Details'!$A$2:$H$2345,4,FALSE) -> 60021.4 | N4: =VLOOKUP($A4,'Hospitalisation Details'!$A$2:$H$2345,5,FALSE) -> tier - 1 | O4: =VLOOKUP($A4,'Hospitalisation Details'!$A$2:$H$2345,6,FALSE) -> tier - 1 | P4: =VLOOKUP($A4,'Hospitalisation Details'!$A$2:$H$2345,7,FALSE) -> R1012 | Q4: =VLOOKUP($A4,'Hospitalisation Details'!$A$2:$H$2345,8,FALSE) -> 118
A5: ='Customer Names'!A5 -> Id4 | B5: =VLOOKUP($A5,'Customer Names'!$A$2:$D$2336,3,FALSE) -> Kelsey | C5: =VLOOKUP($A5,'Medical Examinations'!$A$2:$J$2336,2,FALSE) -> 38.095 | D5: =VLOOKUP($A5,'Medical Examinations'!$A$2:$J$2336,3,FALSE) -> 6.05 | E5: =VLOOKUP($A5,'Medical Examinations'!$A$2:$J$2336,4,FALSE) -> No | F5: =VLOOKUP($A5,'Medical Examinations'!$A$2:$J$2336,5,FALSE) -> No | G5: =VLOOKUP($A5,'Medical Examinations'!$A$2:$J$2336,6,FALSE) -> No | H5: =VLOOKUP($A5,'Medical Examinations'!$A$2:$J$2336,7,FALSE) -> 0 | I5: =VLOOKUP($A5,'Medical Examinations'!$A$2:$J$2336,8,FALSE) -> yes | J5: =VLOOKUP($A5,'Medical Examinations'!$A$2:$J$2336,9,FALSE) -> Obesity | K5: =VLOOKUP($A5,'Medical Examinations'!$A$2:$J$2336,10,FALSE) -> Prediabetes | L5: =VLOOKUP($A5,'Hospitalisation Details'!$A$2:$H$2345,2,FALSE) -> 33395 | M5: =VLOOKUP($A5,'Hospitalisation Details'!$A$2:$H$2345,4,FALSE) -> 58571.07 | N5: =VLOOKUP($A5,'Hospitalisation Details'!$A$2:$H$2345,5,FALSE) -> tier - 1 | O5: =VLOOKUP($A5,'Hospitalisation Details'!$A$2:$H$2345,6,FALSE) -> tier - 3 | P5: =VLOOKUP($A5,'Hospitalisation Details'!$A$2:$H$2345,7,FALSE) -> R1024 | Q5: =VLOOKUP($A5,'Hospitalisation Details'!$A$2:$H$2345,8,FALSE) -> 32
A6: ='Customer Names'!A6 -> Id5 | B6: =VLOOKUP($A6,'Customer Names'!$A$2:$D$2336,3,FALSE) -> Kristyn | C6: =VLOOKUP($A6,'Medical Examinations'!$A$2:$J$2336,2,FALSE) -> 35.53 | D6: =VLOOKUP($A6,'Medical Examinations'!$A$2:$J$2336,3,FALSE) -> 5.45 | E6: =VLOOKUP($A6,'Medical Examinations'!$A$2:$J$2336,4,FALSE) -> No | F6: =VLOOKUP($A6,'Medical Examinations'!$A$2:$J$2336,5,FALSE) -> No | G6: =VLOOKUP($A6,'Medical Examinations'!$A$2:$J$2336,6,FALSE) -> No | H6: =VLOOKUP($A6,'Medical Examinations'!$A$2:$J$2336,7,FALSE) -> 0 | I6: =VLOOKUP($A6,'Medical Examinations'!$A$2:$J$2336,8,FALSE) -> yes | J6: =VLOOKUP($A6,'Medical Examinations'!$A$2:$J$2336,9,FALSE) -> Obesity | K6: =VLOOKUP($A6,'Medical Examinations'!$A$2:$J$2336,10,FALSE) -> Normal | L6: =VLOOKUP($A6,'Hospitalisation Details'!$A$2:$H$2345,2,FALSE) -> 32678 | M6: =VLOOKUP($A6,'Hospitalisation Details'!$A$2:$H$2345,4,FALSE) -> 55135.4 | N6: =VLOOKUP($A6,'Hospitalisation Details'!$A$2:$H$2345,5,FALSE) -> tier - 1 | O6: =VLOOKUP($A6,'Hospitalisation Details'!$A$2:$H$2345,6,FALSE) -> tier - 2 | P6: =VLOOKUP($A6,'Hospitalisation Details'!$A$2:$H$2345,7,FALSE) -> R1012 | Q6: =VLOOKUP($A6,'Hospitalisation Details'!$A$2:$H$2345,8,FALSE) -> 33
A7: ='Customer Names'!A7 -> Id6 | B7: =VLOOKUP($A7,'Customer Names'!$A$2:$D$2336,3,FALSE) -> Russell B. | C7: =VLOOKUP($A7,'Medical Examinations'!$A$2:$J$2336,2,FALSE) -> 32.8 | D7: =VLOOKUP($A7,'Medical Examinations'!$A$2:$J$2336,3,FALSE) -> 6.59 | E7: =VLOOKUP($A7,'Medical Examinations'!$A$2:$J$2336,4,FALSE) -> No | F7: =VLOOKUP($A7,'Medical Examinations'!$A$2:$J$2336,5,FALSE) -> No | G7: =VLOOKUP($A7,'Medical Examinations'!$A$2:$J$2336,6,FALSE) -> No | H7: =VLOOKUP($A7,'Medical Examinations'!$A$2:$J$2336,7,FALSE) -> 0 | I7: =VLOOKUP($A7,'Medical Examinations'!$A$2:$J$2336,8,FALSE) -> yes | J7: =VLOOKUP($A7,'Medical Examinations'!$A$2:$J$2336,9,FALSE) -> Obesity | K7: =VLOOKUP($A7,'Medical Examinations'!$A$2:$J$2336,10,FALSE) -> Diabetes | L7: =VLOOKUP($A7,'Hospitalisation Details'!$A$2:$H$2345,2,FALSE) -> 22862 | M7: =VLOOKUP($A7,'Hospitalisation Details'!$A$2:$H$2345,4,FALSE) -> 52590.83 | N7: =VLOOKUP($A7,'Hospitalisation Details'!$A$2:$H$2345,5,FALSE) -> tier - 1 | O7: =VLOOKUP($A7,'Hospitalisation Details'!$A$2:$H$2345,6,FALSE) -> tier - 3 | P7: =VLOOKUP($A7,'Hospitalisation Details'!$A$2:$H$2345,7,FALSE) -> R1011 | Q7: =VLOOKUP($A7,'Hospitalisation Details'!$A$2:$H$2345,8,FALSE) -> 60
A8: ='Customer Names'!A8 -> Id7 | B8: =VLOOKUP($A8,'Customer Names'!$A$2:$D$2336,3,FALSE) -> Scott | C8: =VLOOKUP($A8,'Medical Examinations'!$A$2:$J$2336,2,FALSE) -> 36.4 | D8: =VLOOKUP($A8,'Medical Examinations'!$A$2:$J$2336,3,FALSE) -> 6.07 | E8: =VLOOKUP($A8,'Medical Examinations'!$A$2:$J$2336,4,FALSE) -> No | F8: =VLOOKUP($A8,'Medical Examinations'!$A$2:$J$2336,5,FALSE) -> No | G8: =VLOOKUP($A8,'Medical Examinations'!$A$2:$J$2336,6,FALSE) -> No | H8: =VLOOKUP($A8,'Medical Examinations'!$A$2:$J$2336,7,FALSE) -> 0 | I8: =VLOOKUP($A8,'Medical Examinations'!$A$2:$J$2336,8,FALSE) -> yes | J8: =VLOOKUP($A8,'Medical Examinations'!$A$2:$J$2336,9,FALSE) -> Obesity | K8: =VLOOKUP($A8,'Medical Examinations'!$A$2:$J$2336,10,FALSE) -> Prediabetes | L8: =VLOOKUP($A8,'Hospitalisation Details'!$A$2:$H$2345,2,FALSE) -> 34634 | M8: =VLOOKUP($A8,'Hospitalisation Details'!$A$2:$H$2345,4,FALSE) -> 51194.56 | N8: =VLOOKUP($A8,'Hospitalisation Details'!$A$2:$H$2345,5,FALSE) -> tier - 1 | O8: =VLOOKUP($A8,'Hospitalisation Details'!$A$2:$H$2345,6,FALSE) -> tier - 3 | P8: =VLOOKUP($A8,'Hospitalisation Details'!$A$2:$H$2345,7,FALSE) -> R1011 | Q8: =VLOOKUP($A8,'Hospitalisation Details'!$A$2:$H$2345,8,FALSE) -> 28
A9: ='Customer Names'!A9 -> Id8 | B9: =VLOOKUP($A9,'Customer Names'!$A$2:$D$2336,3,FALSE) -> Stephen | C9: =VLOOKUP($A9,'Medical Examinations'!$A$2:$J$2336,2,FALSE) -> 36.96 | D9: =VLOOKUP($A9,'Medical Examinations'!$A$2:$J$2336,3,FALSE) -> 7.93 | E9: =VLOOKUP($A9,'Medical Examinations'!$A$2:$J$2336,4,FALSE) -> No | F9: =VLOOKUP($A9,'Medical Examinations'!$A$2:$J$2336,5,FALSE) -> No | G9: =VLOOKUP($A9,'Medical Examinations'!$A$2:$J$2336,6,FALSE) -> No | H9: =VLOOKUP($A9,'Medical Examinations'!$A$2:$J$2336,7,FALSE) -> 3 | I9: =VLOOKUP($A9,'Medical Examinations'!$A$2:$J$2336,8,FALSE) -> yes | J9: =VLOOKUP($A9,'Medical Examinations'!$A$2:$J$2336,9,FALSE) -> Obesity | K9: =VLOOKUP($A9,'Medical Examinations'!$A$2:$J$2336,10,FALSE) -> Diabetes | L9: =VLOOKUP($A9,'Hospitalisation Details'!$A$2:$H$2345,2,FALSE) -> 21363 | M9: =VLOOKUP($A9,'Hospitalisation Details'!$A$2:$H$2345,4,FALSE) -> 49577.66 | N9: =VLOOKUP($A9,'Hospitalisation Details'!$A$2:$H$2345,5,FALSE) -> tier - 2 | O9: =VLOOKUP($A9,'Hospitalisation Details'!$A$2:$H$2345,6,FALSE) -> tier - 2 | P9: =VLOOKUP($A9,'Hospitalisation Details'!$A$2:$H$2345,7,FALSE) -> R1013 | Q9: =VLOOKUP($A9,'Hospitalisation Details'!$A$2:$H$2345,8,FALSE) -> 64
A10: ='Customer Names'!A10 -> Id9 | B10: =VLOOKUP($A10,'Customer Names'!$A$2:$D$2336,3,FALSE) -> Patrick R. | C10: =VLOOKUP($A10,'Medical Examinations'!$A$2:$J$2336,2,FALSE) -> 41.14 | D10: =VLOOKUP($A10,'Medical Examinations'!$A$2:$J$2336,3,FALSE) -> 9.58 | E10: =VLOOKUP($A10,'Medical Examinations'!$A$2:$J$2336,4,FALSE) -> yes | F10: =VLOOKUP($A10,'Medical Examinations'!$A$2:$J$2336,5,FALSE) -> No | G10: =VLOOKUP($A10,'Medical Examinations'!$A$2:$J$2336,6,FALSE) -> Yes | H10: =VLOOKUP($A10,'Medical Examinations'!$A$2:$J$2336,7,FALSE) -> 1 | I10: =VLOOKUP($A10,'Medical Examinations'!$A$2:$J$2336,8,FALSE) -> yes | J10: =VLOOKUP($A10,'Medical Examinations'!$A$2:$J$2336,9,FALSE) -> Obesity | K10: =VLOOKUP($A10,'Medical Examinations'!$A$2:$J$2336,10,FALSE) -> Diabetes | L10: =VLOOKUP($A10,'Hospitalisation Details'!$A$2:$H$2345,2,FALSE) -> 23258 | M10: =VLOOKUP($A10,'Hospitalisation Details'!$A$2:$H$2345,4,FALSE) -> 48970.25 | N10: =VLOOKUP($A10,'Hospitalisation Details'!$A$2:$H$2345,5,FALSE) -> tier - 1 | O10: =VLOOKUP($A10,'Hospitalisation Details'!$A$2:$H$2345,6,FALSE) -> tier - 2 | P10: =VLOOKUP($A10,'Hospitalisation Details'!$A$2:$H$2345,7,FALSE) -> R1013 | Q10: =VLOOKUP($A10,'Hospitalisation Details'!$A$2:$H$2345,8,FALSE) -> 59
A11: ='Customer Names'!A11 -> Id10 | B11: =VLOOKUP($A11,'Customer Names'!$A$2:$D$2336,3,FALSE) -> Brooke N. | C11: =VLOOKUP($A11,'Medical Examinations'!$A$2:$J$2336,2,FALSE) -> 38.06 | D11: =VLOOKUP($A11,'Medical Examinations'!$A$2:$J$2336,3,FALSE) -> 10.79 | E11: =VLOOKUP($A11,'Medical Examinations'!$A$2:$J$2336,4,FALSE) -> No | F11: =VLOOKUP($A11,'Medical Examinations'!$A$2:$J$2336,5,FALSE) -> No | G11: =VLOOKUP($A11,'Medical Examinations'!$A$2:$J$2336,6,FALSE) -> No | H11: =VLOOKUP($A11,'Medical Examinations'!$A$2:$J$2336,7,FALSE) -> 0 | I11: =VLOOKUP($A11,'Medical Examinations'!$A$2:$J$2336,8,FALSE) -> yes | J11: =VLOOKUP($A11,'Medical Examinations'!$A$2:$J$2336,9,FALSE) -> Obesity | K11: =VLOOKUP($A11,'Medical Examinations'!$A$2:$J$2336,10,FALSE) -> Diabetes | L11: =VLOOKUP($A11,'Hospitalisation Details'!$A$2:$H$2345,2,FALSE) -> 28853 | M11: =VLOOKUP($A11,'Hospitalisation Details'!$A$2:$H$2345,4,FALSE) -> 48885.14 | N11: =VLOOKUP($A11,'Hospitalisation Details'!$A$2:$H$2345,5,FALSE) -> tier - 1 | O11: =VLOOKUP($A11,'Hospitalisation Details'!$A$2:$H$2345,6,FALSE) -> tier - 2 | P11: =VLOOKUP($A11,'Hospitalisation Details'!$A$2:$H$2345,7,FALSE) -> R1013 | Q11: =VLOOKUP($A11,'Hospitalisation Details'!$A$2:$H$2345,8,FALSE) -> 44
A12: ='Customer Names'!A12 -> Id11 | B12: =VLOOKUP($A12,'Customer Names'!$A$2:$D$2336,3,FALSE) -> Paola Andrea | C12: =VLOOKUP($A12,'Medical Examinations'!$A$2:$J$2336,2,FALSE) -> 37.7 | D12: =VLOOKUP($A12,'Medical Examinations'!$A$2:$J$2336,3,FALSE) -> 5.96 | E12: =VLOOKUP($A12,'Medical Examinations'!$A$2:$J$2336,4,FALSE) -> yes | F12: =VLOOKUP($A12,'Medical Examinations'!$A$2:$J$2336,5,FALSE) -> No | G12: =VLOOKUP($A12,'Medical Examinations'!$A$2:$J$2336,6,FALSE) -> No | H12: =VLOOKUP($A12,'Medical Examinations'!$A$2:$J$2336,7,FALSE) -> 2 | I12: =VLOOKUP($A12,'Medical Examinations'!$A$2:$J$2336,8,FALSE) -> yes | J12: =VLOOKUP($A12,'Medical Examinations'!$A$2:$J$2336,9,FALSE) -> Obesity | K12: =VLOOKUP($A12,'Medical Examinations'!$A$2:$J$2336,10,FALSE) -> Prediabetes | L12: =VLOOKUP($A12,'Hospitalisation Details'!$A$2:$H$2345,2,FALSE) -> 21753 | M12: =VLOOKUP($A12,'Hospitalisation Details'!$A$2:$H$2345,4,FALSE) -> 48824.45 | N12: =VLOOKUP($A12,'Hospitalisation Details'!$A$2:$H$2345,5,FALSE) -> tier - 2 | O12: =VLOOKUP($A12,'Hospitalisation Details'!$A$2:$H$2345,6,FALSE) -> tier - 1 | P12: =VLOOKUP($A12,'Hospitalisation Details'!$A$2:$H$2345,7,FALSE) -> R1011 | Q12: =VLOOKUP($A12,'Hospitalisation Details'!$A$2:$H$2345,8,FALSE) -> 63
A13: ='Customer Names'!A13 -> Id12 | B13: =VLOOKUP($A13,'Customer Names'!$A$2:$D$2336,3,FALSE) -> David | C13: =VLOOKUP($A13,'Medical Examinations'!$A$2:$J$2336,2,FALSE) -> 42.13 | D13: =VLOOKUP($A13,'Medical Examinations'!$A$2:$J$2336,3,FALSE) -> 11.9 | E13: =VLOOKUP($A13,'Medical Examinations'!$A$2:$J$2336,4,FALSE) -> No | F13: =VLOOKUP($A13,'Medical Examinations'!$A$2:$J$2336,5,FALSE) -> No | G13: =VLOOKUP($A13,'Medical Examinations'!$A$2:$J$2336,6,FALSE) -> No | H13: =VLOOKUP($A13,'Medical Examinations'!$A$2:$J$2336,7,FALSE) -> 0 | I13: =VLOOKUP($A13,'Medical Examinations'!$A$2:$J$2336,8,FALSE) -> yes | J13: =VLOOKUP($A13,'Medical Examinations'!$A$2:$J$2336,9,FALSE) -> Obesity | K13: =VLOOKUP($A13,'Medical Examinations'!$A$2:$J$2336,10,FALSE) -> Diabetes | L13: =VLOOKUP($A13,'Hospitalisation Details'!$A$2:$H$2345,2,FALSE) -> 24042 | M13: =VLOOKUP($A13,'Hospitalisation Details'!$A$2:$H$2345,4,FALSE) -> 48675.52 | N13: =VLOOKUP($A13,'Hospitalisation Details'!$A$2:$H$2345,5,FALSE) -> tier - 1 | O13: =VLOOKUP($A13,'Hospitalisation Details'!$A$2:$H$2345,6,FALSE) -> tier - 2 | P13: =VLOOKUP($A13,'Hospitalisation Details'!$A$2:$H$2345,7,FALSE) -> R1013 | Q13: =VLOOKUP($A13,'Hospitalisation Details'!$A$2:$H$2345,8,FALSE) -> 57
... A2336: ='Customer Names'!A2336 -> Id2335 | B2336: =VLOOKUP($A2336,'Customer Names'!$A$2:$D$2336,3,FALSE) -> Aaron K | C2336: =VLOOKUP($A2336,'Medical Examinations'!$A$2:$J$2336,2,FALSE) -> 17.58 | D2336: =VLOOKUP($A2336,'Medical Examinations'!$A$2:$J$2336,3,FALSE) -> 4.51 | E2336: =VLOOKUP($A2336,'Medical Examinations'!$A$2:$J$2336,4,FALSE) -> No | F2336: =VLOOKUP($A2336,'Medical Examinations'!$A$2:$J$2336,5,FALSE) -> No | G2336: =VLOOKUP($A2336,'Medical Examinations'!$A$2:$J$2336,6,FALSE) -> No | H2336: =VLOOKUP($A2336,'Medical Examinations'!$A$2:$J$2336,7,FALSE) -> 1 | I2336: =VLOOKUP($A2336,'Medical Examinations'!$A$2:$J$2336,8,FALSE) -> No | J2336: =VLOOKUP($A2336,'Medical Examinations'!$A$2:$J$2336,9,FALSE) -> Underweight | K2336: =VLOOKUP($A2336,'Medical Examinations'!$A$2:$J$2336,10,FALSE) -> Normal | L2336: =VLOOKUP($A2336,'Hospitalisation Details'!$A$2:$H$2345,2,FALSE) -> 33794 | M2336: =VLOOKUP($A2336,'Hospitalisation Details'!$A$2:$H$2345,4,FALSE) -> 563.84 | N2336: =VLOOKUP($A2336,'Hospitalisation Details'!$A$2:$H$2345,5,FALSE) -> tier - 2 | O2336: =VLOOKUP($A2336,'Hospitalisation Details'!$A$2:$H$2345,6,FALSE) -> tier - 3 | P2336: =VLOOKUP($A2336,'Hospitalisation Details'!$A$2:$H$2345,7,FALSE) -> R1013 | Q2336: =VLOOKUP($A2336,'Hospitalisation Details'!$A$2:$H$2345,8,FALSE) -> 30

Sheet Healthcare Analysis
A1: Healthcare Analysis
A2: Source: Healthcare sheet | Unknown smoker values excluded from smoker/non-smoker distributions
A4: Smokers | D4: Non-smokers
A5: Cancer history | B5: Count | D5: Cancer history | E5: Count
A6: Yes | B6: =COUNTIFS(Healthcare!$I$2:$I$2336,"yes",Healthcare!$G$2:$G$2336,"yes") -> 84 | D6: Yes | E6: =COUNTIFS(Healthcare!$I$2:$I$2336,"no",Healthcare!$G$2:$G$2336,"yes") -> 307
A7: No | B7: =COUNTIFS(Healthcare!$I$2:$I$2336,"yes",Healthcare!$G$2:$G$2336,"no") -> 404 | D7: No | E7: =COUNTIFS(Healthcare!$I$2:$I$2336,"no",Healthcare!$G$2:$G$2336,"no") -> 1538
A9: Unknown smoker rows excluded | B9: =COUNTIF(Healthcare!$I$2:$I$2336,"~?") -> 2 | D9: Known cancer history rows | E9: =SUM(E6:E7) -> 1845
A12: Transplant comparison
A13: Transplant history | B13: Total major surgeries | C13: Average HbA1C
A14: Yes | B14: =SUMIF(Healthcare!$F$2:$F$2336,A14,Healthcare!$H$2:$H$2336) -> 162 | C14: =AVERAGEIF(Healthcare!$F$2:$F$2336,A14,Healthcare!$D$2:$D$2336) -> 5.1876389
A15: No | B15: =SUMIF(Healthcare!$F$2:$F$2336,A15,Healthcare!$H$2:$H$2336) -> 1417 | C15: =AVERAGEIF(Healthcare!$F$2:$F$2336,A15,Healthcare!$D$2:$D$2336) -> 6.6704427
A17: Difference (Yes - No) | B17: =B14-B15 -> -1255 | C17: =C14-C15 -> -1.4828038
A20: Smokers with cancer history | B20: =B6/SUM(B6:B7) -> 0.17213115
A21: Non-smokers with cancer history | B21: =E6/SUM(E6:E7) -> 0.16639566
A22: Transplant surgery difference | B22: =B17 -> -1255
A23: Transplant HbA1C difference | B23: =C17 -> -1.4828038
A27: HbA1C comparison
A28: Transplant history | B28: Average HbA1C
A29: Yes | B29: =C14 -> 5.1876389
A30: No | B30: =C15 -> 6.6704427
A33: Average Healthcare Charges by Weight and Diabetes Status
A34: Weight Status | B34: Normal | C34: Prediabetes | D34: Diabetes
A35: Underweight | B35: =AVERAGEIFS(Healthcare!$M$2:$M$2336,Healthcare!$J$2:$J$2336,$A35,Healthcare!$K$2:$K$2336,B$34) -> 6911.0056 | C35: =AVERAGEIFS(Healthcare!$M$2:$M$2336,Healthcare!$J$2:$J$2336,$A35,Healthcare!$K$2:$K$2336,C$34) -> 5647.7483 | D35: =AVERAGEIFS(Healthcare!$M$2:$M$2336,Healthcare!$J$2:$J$2336,$A35,Healthcare!$K$2:$K$2336,D$34) -> 7442.9649
A36: Normal Weight | B36: =AVERAGEIFS(Healthcare!$M$2:$M$2336,Healthcare!$J$2:$J$2336,$A36,Healthcare!$K$2:$K$2336,B$34) -> 7938.5057 | C36: =AVERAGEIFS(Healthcare!$M$2:$M$2336,Healthcare!$J$2:$J$2336,$A36,Healthcare!$K$2:$K$2336,C$34) -> 10492.131 | D36: =AVERAGEIFS(Healthcare!$M$2:$M$2336,Healthcare!$J$2:$J$2336,$A36,Healthcare!$K$2:$K$2336,D$34) -> 12447.613
A37: Overweight | B37: =AVERAGEIFS(Healthcare!$M$2:$M$2336,Healthcare!$J$2:$J$2336,$A37,Healthcare!$K$2:$K$2336,B$34) -> 10327.157 | C37: =AVERAGEIFS(Healthcare!$M$2:$M$2336,Healthcare!$J$2:$J$2336,$A37,Healthcare!$K$2:$K$2336,C$34) -> 9737.9402 | D37: =AVERAGEIFS(Healthcare!$M$2:$M$2336,Healthcare!$J$2:$J$2336,$A37,Healthcare!$K$2:$K$2336,D$34) -> 14269.014
A38: Obesity | B38: =AVERAGEIFS(Healthcare!$M$2:$M$2336,Healthcare!$J$2:$J$2336,$A38,Healthcare!$K$2:$K$2336,B$34) -> 15188.437 | C38: =AVERAGEIFS(Healthcare!$M$2:$M$2336,Healthcare!$J$2:$J$2336,$A38,Healthcare!$K$2:$K$2336,C$34) -> 15353.902 | D38: =AVERAGEIFS(Healthcare!$M$2:$M$2336,Healthcare!$J$2:$J$2336,$A38,Healthcare!$K$2:$K$2336,D$34) -> 19347.657
A41: Average Healthcare Charges by Hospital Tier and State
A42: State ID | B42: tier - 1 | C42: tier - 2 | D42: tier - 3
A43: R1011 | B43: =IF(COUNTIFS(Healthcare!$P$2:$P$2336,$A43,Healthcare!$N$2:$N$2336,B$42)=0,"",AVERAGEIFS(Healthcare!$M$2:$M$2336,Healthcare!$P$2:$P$2336,$A43,Healthcare!$N$2:$N$2336,B$42)) -> 33081.374 | C43: =IF(COUNTIFS(Healthcare!$P$2:$P$2336,$A43,Healthcare!$N$2:$N$2336,C$42)=0,"",AVERAGEIFS(Healthcare!$M$2:$M$2336,Healthcare!$P$2:$P$2336,$A43,Healthcare!$N$2:$N$2336,C$42)) -> 18997.281 | D43: =IF(COUNTIFS(Healthcare!$P$2:$P$2336,$A43,Healthcare!$N$2:$N$2336,D$42)=0,"",AVERAGEIFS(Healthcare!$M$2:$M$2336,Healthcare!$P$2:$P$2336,$A43,Healthcare!$N$2:$N$2336,D$42)) -> 9250.3618
A44: R1012 | B44: =IF(COUNTIFS(Healthcare!$P$2:$P$2336,$A44,Healthcare!$N$2:$N$2336,B$42)=0,"",AVERAGEIFS(Healthcare!$M$2:$M$2336,Healthcare!$P$2:$P$2336,$A44,Healthcare!$N$2:$N$2336,B$42)) -> 26111.458 | C44: =IF(COUNTIFS(Healthcare!$P$2:$P$2336,$A44,Healthcare!$N$2:$N$2336,C$42)=0,"",AVERAGEIFS(Healthcare!$M$2:$M$2336,Healthcare!$P$2:$P$2336,$A44,Healthcare!$N$2:$N$2336,C$42)) -> 10334.279 | D44: =IF(COUNTIFS(Healthcare!$P$2:$P$2336,$A44,Healthcare!$N$2:$N$2336,D$42)=0,"",AVERAGEIFS(Healthcare!$M$2:$M$2336,Healthcare!$P$2:$P$2336,$A44,Healthcare!$N$2:$N$2336,D$42)) -> 10179.942
A45: R1013 | B45: =IF(COUNTIFS(Healthcare!$P$2:$P$2336,$A45,Healthcare!$N$2:$N$2336,B$42)=0,"",AVERAGEIFS(Healthcare!$M$2:$M$2336,Healthcare!$P$2:$P$2336,$A45,Healthcare!$N$2:$N$2336,B$42)) -> 31328.102 | C45: =IF(COUNTIFS(Healthcare!$P$2:$P$2336,$A45,Healthcare!$N$2:$N$2336,C$42)=0,"",AVERAGEIFS(Healthcare!$M$2:$M$2336,Healthcare!$P$2:$P$2336,$A45,Healthcare!$N$2:$N$2336,C$42)) -> 8459.9777 | D45: =IF(COUNTIFS(Healthcare!$P$2:$P$2336,$A45,Healthcare!$N$2:$N$2336,D$42)=0,"",AVERAGEIFS(Healthcare!$M$2:$M$2336,Healthcare!$P$2:$P$2336,$A45,Healthcare!$N$2:$N$2336,D$42)) -> 6890.7568
A46: R1014 | B46: =IF(COUNTIFS(Healthcare!$P$2:$P$2336,$A46,Healthcare!$N$2:$N$2336,B$42)=0,"",AVERAGEIFS(Healthcare!$M$2:$M$2336,Healthcare!$P$2:$P$2336,$A46,Healthcare!$N$2:$N$2336,B$42)) -> 13891.86 | C46: =IF(COUNTIFS(Healthcare!$P$2:$P$2336,$A46,Healthcare!$N$2:$N$2336,C$42)=0,"",AVERAGEIFS(Healthcare!$M$2:$M$2336,Healthcare!$P$2:$P$2336,$A46,Healthcare!$N$2:$N$2336,C$42)) -> 2395.17 | D46: =IF(COUNTIFS(Healthcare!$P$2:$P$2336,$A46,Healthcare!$N$2:$N$2336,D$42)=0,"",AVERAGEIFS(Healthcare!$M$2:$M$2336,Healthcare!$P$2:$P$2336,$A46,Healthcare!$N$2:$N$2336,D$42)) -> 16950.485
A47: R1015 | B47: =IF(COUNTIFS(Healthcare!$P$2:$P$2336,$A47,Healthcare!$N$2:$N$2336,B$42)=0,"",AVERAGEIFS(Healthcare!$M$2:$M$2336,Healthcare!$P$2:$P$2336,$A47,Healthcare!$N$2:$N$2336,B$42)) -> 21523.52 | C47: =IF(COUNTIFS(Healthcare!$P$2:$P$2336,$A47,Healthcare!$N$2:$N$2336,C$42)=0,"",AVERAGEIFS(Healthcare!$M$2:$M$2336,Healthcare!$P$2:$P$2336,$A47,Healthcare!$N$2:$N$2336,C$42)) -> 15675.543 | D47: =IF(COUNTIFS(Healthcare!$P$2:$P$2336,$A47,Healthcare!$N$2:$N$2336,D$42)=0,"",AVERAGEIFS(Healthcare!$M$2:$M$2336,Healthcare!$P$2:$P$2336,$A47,Healthcare!$N$2:$N$2336,D$42)) -> 7570.755
A48: R1016 | B48: =IF(COUNTIFS(Healthcare!$P$2:$P$2336,$A48,Healthcare!$N$2:$N$2336,B$42)=0,"",AVERAGEIFS(Healthcare!$M$2:$M$2336,Healthcare!$P$2:$P$2336,$A48,Healthcare!$N$2:$N$2336,B$42)) -> 39868.616 | C48: =IF(COUNTIFS(Healthcare!$P$2:$P$2336,$A48,Healthcare!$N$2:$N$2336,C$42)=0,"",AVERAGEIFS(Healthcare!$M$2:$M$2336,Healthcare!$P$2:$P$2336,$A48,Healthcare!$N$2:$N$2336,C$42)) -> 16075.963 | D48: =IF(COUNTIFS(Healthcare!$P$2:$P$2336,$A48,Healthcare!$N$2:$N$2336,D$42)=0,"",AVERAGEIFS(Healthcare!$M$2:$M$2336,Healthcare!$P$2:$P$2336,$A48,Healthcare!$N$2:$N$2336,D$42)) -> 8133.0084
A49: R1017 | B49: =IF(COUNTIFS(Healthcare!$P$2:$P$2336,$A49,Healthcare!$N$2:$N$2336,B$42)=0,"",AVERAGEIFS(Healthcare!$M$2:$M$2336,Healthcare!$P$2:$P$2336,$A49,Healthcare!$N$2:$N$2336,B$42)) -> 34070.596 | C49: =IF(COUNTIFS(Healthcare!$P$2:$P$2336,$A49,Healthcare!$N$2:$N$2336,C$42)=0,"",AVERAGEIFS(Healthcare!$M$2:$M$2336,Healthcare!$P$2:$P$2336,$A49,Healthcare!$N$2:$N$2336,C$42)) -> 11365.622 | D49: =IF(COUNTIFS(Healthcare!$P$2:$P$2336,$A49,Healthcare!$N$2:$N$2336,D$42)=0,"",AVERAGEIFS(Healthcare!$M$2:$M$2336,Healthcare!$P$2:$P$2336,$A49,Healthcare!$N$2:$N$2336,D$42)) -> 8667.3662
A50: R1018 | B50: =IF(COUNTIFS(Healthcare!$P$2:$P$2336,$A50,Healthcare!$N$2:$N$2336,B$42)=0,"",AVERAGEIFS(Healthcare!$M$2:$M$2336,Healthcare!$P$2:$P$2336,$A50,Healthcare!$N$2:$N$2336,B$42)) -> 33475.82 | C50: =IF(COUNTIFS(Healthcare!$P$2:$P$2336,$A50,Healthcare!$N$2:$N$2336,C$42)=0,"",AVERAGEIFS(Healthcare!$M$2:$M$2336,Healthcare!$P$2:$P$2336,$A50,Healthcare!$N$2:$N$2336,C$42)) -> 10139.553 | D50: =IF(COUNTIFS(Healthcare!$P$2:$P$2336,$A50,Healthcare!$N$2:$N$2336,D$42)=0,"",AVERAGEIFS(Healthcare!$M$2:$M$2336,Healthcare!$P$2:$P$2336,$A50,Healthcare!$N$2:$N$2336,D$42)) -> 12570.97
A51: R1019 | B51: =IF(COUNTIFS(Healthcare!$P$2:$P$2336,$A51,Healthcare!$N$2:$N$2336,B$42)=0,"",AVERAGEIFS(Healthcare!$M$2:$M$2336,Healthcare!$P$2:$P$2336,$A51,Healthcare!$N$2:$N$2336,B$42)) -> 27621.61 | C51: =IF(COUNTIFS(Healthcare!$P$2:$P$2336,$A51,Healthcare!$N$2:$N$2336,C$42)=0,"",AVERAGEIFS(Healthcare!$M$2:$M$2336,Healthcare!$P$2:$P$2336,$A51,Healthcare!$N$2:$N$2336,C$42)) -> 8116.72 | D51: =IF(COUNTIFS(Healthcare!$P$2:$P$2336,$A51,Healthcare!$N$2:$N$2336,D$42)=0,"",AVERAGEIFS(Healthcare!$M$2:$M$2336,Healthcare!$P$2:$P$2336,$A51,Healthcare!$N$2:$N$2336,D$42)) -> 12706.976
A52: R1020 | B52: =IF(COUNTIFS(Healthcare!$P$2:$P$2336,$A52,Healthcare!$N$2:$N$2336,B$42)=0,"",AVERAGEIFS(Healthcare!$M$2:$M$2336,Healthcare!$P$2:$P$2336,$A52,Healthcare!$N$2:$N$2336,B$42)) | C52: =IF(COUNTIFS(Healthcare!$P$2:$P$2336,$A52,Healthcare!$N$2:$N$2336,C$42)=0,"",AVERAGEIFS(Healthcare!$M$2:$M$2336,Healthcare!$P$2:$P$2336,$A52,Healthcare!$N$2:$N$2336,C$42)) -> 6760.5433 | D52: =IF(COUNTIFS(Healthcare!$P$2:$P$2336,$A52,Healthcare!$N$2:$N$2336,D$42)=0,"",AVERAGEIFS(Healthcare!$M$2:$M$2336,Healthcare!$P$2:$P$2336,$A52,Healthcare!$N$2:$N$2336,D$42)) -> 11716.453
A53: R1021 | B53: =IF(COUNTIFS(Healthcare!$P$2:$P$2336,$A53,Healthcare!$N$2:$N$2336,B$42)=0,"",AVERAGEIFS(Healthcare!$M$2:$M$2336,Healthcare!$P$2:$P$2336,$A53,Healthcare!$N$2:$N$2336,B$42)) | C53: =IF(COUNTIFS(Healthcare!$P$2:$P$2336,$A53,Healthcare!$N$2:$N$2336,C$42)=0,"",AVERAGEIFS(Healthcare!$M$2:$M$2336,Healthcare!$P$2:$P$2336,$A53,Healthcare!$N$2:$N$2336,C$42)) -> 7668.1787 | D53: =IF(COUNTIFS(Healthcare!$P$2:$P$2336,$A53,Healthcare!$N$2:$N$2336,D$42)=0,"",AVERAGEIFS(Healthcare!$M$2:$M$2336,Healthcare!$P$2:$P$2336,$A53,Healthcare!$N$2:$N$2336,D$42)) -> 11518.786
A54: R1022 | B54: =IF(COUNTIFS(Healthcare!$P$2:$P$2336,$A54,Healthcare!$N$2:$N$2336,B$42)=0,"",AVERAGEIFS(Healthcare!$M$2:$M$2336,Healthcare!$P$2:$P$2336,$A54,Healthcare!$N$2:$N$2336,B$42)) | C54: =IF(COUNTIFS(Healthcare!$P$2:$P$2336,$A54,Healthcare!$N$2:$N$2336,C$42)=0,"",AVERAGEIFS(Healthcare!$M$2:$M$2336,Healthcare!$P$2:$P$2336,$A54,Healthcare!$N$2:$N$2336,C$42)) -> 10102.027 | D54: =IF(COUNTIFS(Healthcare!$P$2:$P$2336,$A54,Healthcare!$N$2:$N$2336,D$42)=0,"",AVERAGEIFS(Healthcare!$M$2:$M$2336,Healthcare!$P$2:$P$2336,$A54,Healthcare!$N$2:$N$2336,D$42)) -> 11637.812
...

Sheet Dashboard
A1: Healthcare Insights Dashboard | T1: Filter controls | AA1: VisibleRow | AB1: Age | AC1: BMI | AD1: HbA1C | AE1: Charges | AF1: Age | AG1: BMI | AH1: Age | AI1: HbA1C | AJ1: Age | AK1: Charges
A2: Interactive health outcomes and charges view | slicers filter every visualization | AA2: =SUBTOTAL(103,Healthcare!A2) -> 1 | AB2: =IF($AA2=1,Healthcare!Q2,NA()) -> 54 | AC2: =IF($AA2=1,Healthcare!C2,NA()) -> 47.41 | AD2: =IF($AA2=1,Healthcare!D2,NA()) -> 7.47 | AE2: =IF($AA2=1,Healthcare!M2,NA()) -> 63770.43 | AF2: =AB2 -> 54 | AG2: =AC2 -> 47.41 | AH2: =AB2 -> 54 | AI2: =AD2 -> 7.47 | AJ2: =AB2 -> 54 | AK2: =AE2 -> 63770.43
AA3: =SUBTOTAL(103,Healthcare!A3) -> 1 | AB3: =IF($AA3=1,Healthcare!Q3,NA()) -> 46 | AC3: =IF($AA3=1,Healthcare!C3,NA()) -> 30.36 | AD3: =IF($AA3=1,Healthcare!D3,NA()) -> 5.77 | AE3: =IF($AA3=1,Healthcare!M3,NA()) -> 62592.87 | AF3: =AB3 -> 46 | AG3: =AC3 -> 30.36 | AH3: =AB3 -> 46 | AI3: =AD3 -> 5.77 | AJ3: =AB3 -> 46 | AK3: =AE3 -> 62592.87
A4: Visible patients | D4: Average charges | G4: Average age | J4: Average HbA1C | AA4: =SUBTOTAL(103,Healthcare!A4) -> 1 | AB4: =IF($AA4=1,Healthcare!Q4,NA()) -> 118 | AC4: =IF($AA4=1,Healthcare!C4,NA()) -> 34.485 | AD4: =IF($AA4=1,Healthcare!D4,NA()) -> 11.87 | AE4: =IF($AA4=1,Healthcare!M4,NA()) -> 60021.4 | AF4: =AB4 -> 118 | AG4: =AC4 -> 34.485 | AH4: =AB4 -> 118 | AI4: =AD4 -> 11.87 | AJ4: =AB4 -> 118 | AK4: =AE4 -> 60021.4
A5: =SUM($AA$2:$AA$2336) -> 2335 | D5: =IFERROR(SUMPRODUCT($AA$2:$AA$2336,Healthcare!$M$2:$M$2336)/SUM($AA$2:$AA$2336),0) -> 13529.918 | G5: =IFERROR(SUMPRODUCT($AA$2:$AA$2336,Healthcare!$Q$2:$Q$2336)/SUM($AA$2:$AA$2336),0) -> 39.304069 | J5: =IFERROR(SUMPRODUCT($AA$2:$AA$2336,Healthcare!$D$2:$D$2336)/SUM($AA$2:$AA$2336),0) -> 6.5789979 | AA5: =SUBTOTAL(103,Healthcare!A5) -> 1 | AB5: =IF($AA5=1,Healthcare!Q5,NA()) -> 32 | AC5: =IF($AA5=1,Healthcare!C5,NA()) -> 38.095 | AD5: =IF($AA5=1,Healthcare!D5,NA()) -> 6.05 | AE5: =IF($AA5=1,Healthcare!M5,NA()) -> 58571.07 | AF5: =AB5 -> 32 | AG5: =AC5 -> 38.095 | AH5: =AB5 -> 32 | AI5: =AD5 -> 6.05 | AJ5: =AB5 -> 32 | AK5: =AE5 -> 58571.07
AA6: =SUBTOTAL(103,Healthcare!A6) -> 1 | AB6: =IF($AA6=1,Healthcare!Q6,NA()) -> 33 | AC6: =IF($AA6=1,Healthcare!C6,NA()) -> 35.53 | AD6: =IF($AA6=1,Healthcare!D6,NA()) -> 5.45 | AE6: =IF($AA6=1,Healthcare!M6,NA()) -> 55135.4 | AF6: =AB6 -> 33 | AG6: =AC6 -> 35.53 | AH6: =AB6 -> 33 | AI6: =AD6 -> 5.45 | AJ6: =AB6 -> 33 | AK6: =AE6 -> 55135.4
AA7: =SUBTOTAL(103,Healthcare!A7) -> 1 | AB7: =IF($AA7=1,Healthcare!Q7,NA()) -> 60 | AC7: =IF($AA7=1,Healthcare!C7,NA()) -> 32.8 | AD7: =IF($AA7=1,Healthcare!D7,NA()) -> 6.59 | AE7: =IF($AA7=1,Healthcare!M7,NA()) -> 52590.83 | AF7: =AB7 -> 60 | AG7: =AC7 -> 32.8 | AH7: =AB7 -> 60 | AI7: =AD7 -> 6.59 | AJ7: =AB7 -> 60 | AK7: =AE7 -> 52590.83
AA8: =SUBTOTAL(103,Healthcare!A8) -> 1 | AB8: =IF($AA8=1,Healthcare!Q8,NA()) -> 28 | AC8: =IF($AA8=1,Healthcare!C8,NA()) -> 36.4 | AD8: =IF($AA8=1,Healthcare!D8,NA()) -> 6.07 | AE8: =IF($AA8=1,Healthcare!M8,NA()) -> 51194.56 | AF8: =AB8 -> 28 | AG8: =AC8 -> 36.4 | AH8: =AB8 -> 28 | AI8: =AD8 -> 6.07 | AJ8: =AB8 -> 28 | AK8: =AE8 -> 51194.56
A9: Cancer history - smokers | B9: Count | D9: Cancer history - non-smokers | E9: Count | G9: Transplant history | H9: Total surgeries | I9: Avg HbA1C | K9: Weight Status | L9: Normal | M9: Prediabetes | N9: Diabetes | P9: State ID | Q9: tier - 1 | R9: tier - 2 | S9: tier - 3 | AA9: =SUBTOTAL(103,Healthcare!A9) -> 1 | AB9: =IF($AA9=1,Healthcare!Q9,NA()) -> 64 | AC9: =IF($AA9=1,Healthcare!C9,NA()) -> 36.96 | AD9: =IF($AA9=1,Healthcare!D9,NA()) -> 7.93 | AE9: =IF($AA9=1,Healthcare!M9,NA()) -> 49577.66 | AF9: =AB9 -> 64 | AG9: =AC9 -> 36.96 | AH9: =AB9 -> 64 | AI9: =AD9 -> 7.93 | AJ9: =AB9 -> 64 | AK9: =AE9 -> 49577.66
A10: Yes | B10: {=SUMPRODUCT($AA$2:$AA$2336,--(Healthcare!$I$2:$I$2336="yes"),--(Healthcare!$G$2:$G$2336=$A10))} -> 84 | D10: Yes | E10: {=SUMPRODUCT($AA$2:$AA$2336,--(Healthcare!$I$2:$I$2336="no"),--(Healthcare!$G$2:$G$2336=$D10))} -> 307 | G10: Yes | H10: {=SUMPRODUCT($AA$2:$AA$2336,--(Healthcare!$F$2:$F$2336=$G10),Healthcare!$H$2:$H$2336)} -> 162 | I10: {=IFERROR(SUMPRODUCT($AA$2:$AA$2336,--(Healthcare!$F$2:$F$2336=$G10),Healthcare!$D$2:$D$2336)/SUMPRODUCT($AA$2:$AA$2336,--(Healthcare!$F$2:$F$2336=$G10)),"")} -> 5.1876389 | K10: Underweight | L10: {=IFERROR(SUMPRODUCT($AA$2:$AA$2336,--(Healthcare!$J$2:$J$2336=$K10),--(Healthcare!$K$2:$K$2336=L$9),Healthcare!$M$2:$M$2336)/SUMPRODUCT($AA$2:$AA$2336,--(Healthcare!$J$2:$J$2336=$K10),--(Healthcare!$K$2:$K$2336=L$9)),"")} -> 6911.0056 | M10: {=IFERROR(SUMPRODUCT($AA$2:$AA$2336,--(Healthcare!$J$2:$J$2336=$K10),--(Healthcare!$K$2:$K$2336=M$9),Healthcare!$M$2:$M$2336)/SUMPRODUCT($AA$2:$AA$2336,--(Healthcare!$J$2:$J$2336=$K10),--(Healthcare!$K$2:$K$2336=M$9)),"")} -> 5647.7483 | N10: {=IFERROR(SUMPRODUCT($AA$2:$AA$2336,--(Healthcare!$J$2:$J$2336=$K10),--(Healthcare!$K$2:$K$2336=N$9),Healthcare!$M$2:$M$2336)/SUMPRODUCT($AA$2:$AA$2336,--(Healthcare!$J$2:$J$2336=$K10),--(Healthcare!$K$2:$K$2336=N$9)),"")} -> 7442.9649 | P10: ='Healthcare Analysis'!A43 -> R1011 | Q10: {=IFERROR(SUMPRODUCT($AA$2:$AA$2336,--(Healthcare!$P$2:$P$2336=$P10),--(Healthcare!$N$2:$N$2336=Q$9),Healthcare!$M$2:$M$2336)/SUMPRODUCT($AA$2:$AA$2336,--(Healthcare!$P$2:$P$2336=$P10),--(Healthcare!$N$2:$N$2336=Q$9)),"")} -> 33081.374 | R10: {=IFERROR(SUMPRODUCT($AA$2:$AA$2336,--(Healthcare!$P$2:$P$2336=$P10),--(Healthcare!$N$2:$N$2336=R$9),Healthcare!$M$2:$M$2336)/SUMPRODUCT($AA$2:$AA$2336,--(Healthcare!$P$2:$P$2336=$P10),--(Healthcare!$N$2:$N$2336=R$9)),"")} -> 18997.281 | S10: {=IFERROR(SUMPRODUCT($AA$2:$AA$2336,--(Healthcare!$P$2:$P$2336=$P10),--(Healthcare!$N$2:$N$2336=S$9),Healthcare!$M$2:$M$2336)/SUMPRODUCT($AA$2:$AA$2336,--(Healthcare!$P$2:$P$2336=$P10),--(Healthcare!$N$2:$N$2336=S$9)),"")} -> 9250.3618 | AA10: =SUBTOTAL(103,Healthcare!A10) -> 1 | AB10: =IF($AA10=1,Healthcare!Q10,NA()) -> 59 | AC10: =IF($AA10=1,Healthcare!C10,NA()) -> 41.14 | AD10: =IF($AA10=1,Healthcare!D10,NA()) -> 9.58 | AE10: =IF($AA10=1,Healthcare!M10,NA()) -> 48970.25 | AF10: =AB10 -> 59 | AG10: =AC10 -> 41.14 | AH10: =AB10 -> 59 | AI10: =AD10 -> 9.58 | AJ10: =AB10 -> 59 | AK10: =AE10 -> 48970.25
A11: No | B11: {=SUMPRODUCT($AA$2:$AA$2336,--(Healthcare!$I$2:$I$2336="yes"),--(Healthcare!$G$2:$G$2336=$A11))} -> 404 | D11: No | E11: {=SUMPRODUCT($AA$2:$AA$2336,--(Healthcare!$I$2:$I$2336="no"),--(Healthcare!$G$2:$G$2336=$D11))} -> 1538 | G11: No | H11: {=SUMPRODUCT($AA$2:$AA$2336,--(Healthcare!$F$2:$F$2336=$G11),Healthcare!$H$2:$H$2336)} -> 1417 | I11: {=IFERROR(SUMPRODUCT($AA$2:$AA$2336,--(Healthcare!$F$2:$F$2336=$G11),Healthcare!$D$2:$D$2336)/SUMPRODUCT($AA$2:$AA$2336,--(Healthcare!$F$2:$F$2336=$G11)),"")} -> 6.6704427 | K11: Normal Weight | L11: {=IFERROR(SUMPRODUCT($AA$2:$AA$2336,--(Healthcare!$J$2:$J$2336=$K11),--(Healthcare!$K$2:$K$2336=L$9),Healthcare!$M$2:$M$2336)/SUMPRODUCT($AA$2:$AA$2336,--(Healthcare!$J$2:$J$2336=$K11),--(Healthcare!$K$2:$K$2336=L$9)),"")} -> 7938.5057 | M11: {=IFERROR(SUMPRODUCT($AA$2:$AA$2336,--(Healthcare!$J$2:$J$2336=$K11),--(Healthcare!$K$2:$K$2336=M$9),Healthcare!$M$2:$M$2336)/SUMPRODUCT($AA$2:$AA$2336,--(Healthcare!$J$2:$J$2336=$K11),--(Healthcare!$K$2:$K$2336=M$9)),"")} -> 10492.131 | N11: {=IFERROR(SUMPRODUCT($AA$2:$AA$2336,--(Healthcare!$J$2:$J$2336=$K11),--(Healthcare!$K$2:$K$2336=N$9),Healthcare!$M$2:$M$2336)/SUMPRODUCT($AA$2:$AA$2336,--(Healthcare!$J$2:$J$2336=$K11),--(Healthcare!$K$2:$K$2336=N$9)),"")} -> 12447.613 | P11: ='Healthcare Analysis'!A44 -> R1012 | Q11: {=IFERROR(SUMPRODUCT($AA$2:$AA$2336,--(Healthcare!$P$2:$P$2336=$P11),--(Healthcare!$N$2:$N$2336=Q$9),Healthcare!$M$2:$M$2336)/SUMPRODUCT($AA$2:$AA$2336,--(Healthcare!$P$2:$P$2336=$P11),--(Healthcare!$N$2:$N$2336=Q$9)),"")} -> 26111.458 | R11: {=IFERROR(SUMPRODUCT($AA$2:$AA$2336,--(Healthcare!$P$2:$P$2336=$P11),--(Healthcare!$N$2:$N$2336=R$9),Healthcare!$M$2:$M$2336)/SUMPRODUCT($AA$2:$AA$2336,--(Healthcare!$P$2:$P$2336=$P11),--(Healthcare!$N$2:$N$2336=R$9)),"")} -> 10334.279 | S11: {=IFERROR(SUMPRODUCT($AA$2:$AA$2336,--(Healthcare!$P$2:$P$2336=$P11),--(Healthcare!$N$2:$N$2336=S$9),Healthcare!$M$2:$M$2336)/SUMPRODUCT($AA$2:$AA$2336,--(Healthcare!$P$2:$P$2336=$P11),--(Healthcare!$N$2:$N$2336=S$9)),"")} -> 10179.942 | AA11: =SUBTOTAL(103,Healthcare!A11) -> 1 | AB11: =IF($AA11=1,Healthcare!Q11,NA()) -> 44 | AC11: =IF($AA11=1,Healthcare!C11,NA()) -> 38.06 | AD11: =IF($AA11=1,Healthcare!D11,NA()) -> 10.79 | AE11: =IF($AA11=1,Healthcare!M11,NA()) -> 48885.14 | AF11: =AB11 -> 44 | AG11: =AC11 -> 38.06 | AH11: =AB11 -> 44 | AI11: =AD11 -> 10.79 | AJ11: =AB11 -> 44 | AK11: =AE11 -> 48885.14
K12: Overweight | L12: {=IFERROR(SUMPRODUCT($AA$2:$AA$2336,--(Healthcare!$J$2:$J$2336=$K12),--(Healthcare!$K$2:$K$2336=L$9),Healthcare!$M$2:$M$2336)/SUMPRODUCT($AA$2:$AA$2336,--(Healthcare!$J$2:$J$2336=$K12),--(Healthcare!$K$2:$K$2336=L$9)),"")} -> 10327.157 | M12: {=IFERROR(SUMPRODUCT($AA$2:$AA$2336,--(Healthcare!$J$2:$J$2336=$K12),--(Healthcare!$K$2:$K$2336=M$9),Healthcare!$M$2:$M$2336)/SUMPRODUCT($AA$2:$AA$2336,--(Healthcare!$J$2:$J$2336=$K12),--(Healthcare!$K$2:$K$2336=M$9)),"")} -> 9737.9402 | N12: {=IFERROR(SUMPRODUCT($AA$2:$AA$2336,--(Healthcare!$J$2:$J$2336=$K12),--(Healthcare!$K$2:$K$2336=N$9),Healthcare!$M$2:$M$2336)/SUMPRODUCT($AA$2:$AA$2336,--(Healthcare!$J$2:$J$2336=$K12),--(Healthcare!$K$2:$K$2336=N$9)),"")} -> 14269.014 | P12: ='Healthcare Analysis'!A45 -> R1013 | Q12: {=IFERROR(SUMPRODUCT($AA$2:$AA$2336,--(Healthcare!$P$2:$P$2336=$P12),--(Healthcare!$N$2:$N$2336=Q$9),Healthcare!$M$2:$M$2336)/SUMPRODUCT($AA$2:$AA$2336,--(Healthcare!$P$2:$P$2336=$P12),--(Healthcare!$N$2:$N$2336=Q$9)),"")} -> 31328.102 | R12: {=IFERROR(SUMPRODUCT($AA$2:$AA$2336,--(Healthcare!$P$2:$P$2336=$P12),--(Healthcare!$N$2:$N$2336=R$9),Healthcare!$M$2:$M$2336)/SUMPRODUCT($AA$2:$AA$2336,--(Healthcare!$P$2:$P$2336=$P12),--(Healthcare!$N$2:$N$2336=R$9)),"")} -> 8459.9777 | S12: {=IFERROR(SUMPRODUCT($AA$2:$AA$2336,--(Healthcare!$P$2:$P$2336=$P12),--(Healthcare!$N$2:$N$2336=S$9),Healthcare!$M$2:$M$2336)/SUMPRODUCT($AA$2:$AA$2336,--(Healthcare!$P$2:$P$2336=$P12),--(Healthcare!$N$2:$N$2336=S$9)),"")} -> 6890.7568 | AA12: =SUBTOTAL(103,Healthcare!A12) -> 1 | AB12: =IF($AA12=1,Healthcare!Q12,NA()) -> 63 | AC12: =IF($AA12=1,Healthcare!C12,NA()) -> 37.7 | AD12: =IF($AA12=1,Healthcare!D12,NA()) -> 5.96 | AE12: =IF($AA12=1,Healthcare!M12,NA()) -> 48824.45 | AF12: =AB12 -> 63 | AG12: =AC12 -> 37.7 | AH12: =AB12 -> 63 | AI12: =AD12 -> 5.96 | AJ12: =AB12 -> 63 | AK12: =AE12 -> 48824.45
K13: Obesity | L13: {=IFERROR(SUMPRODUCT($AA$2:$AA$2336,--(Healthcare!$J$2:$J$2336=$K13),--(Healthcare!$K$2:$K$2336=L$9),Healthcare!$M$2:$M$2336)/SUMPRODUCT($AA$2:$AA$2336,--(Healthcare!$J$2:$J$2336=$K13),--(Healthcare!$K$2:$K$2336=L$9)),"")} -> 15188.437 | M13: {=IFERROR(SUMPRODUCT($AA$2:$AA$2336,--(Healthcare!$J$2:$J$2336=$K13),--(Healthcare!$K$2:$K$2336=M$9),Healthcare!$M$2:$M$2336)/SUMPRODUCT($AA$2:$AA$2336,--(Healthcare!$J$2:$J$2336=$K13),--(Healthcare!$K$2:$K$2336=M$9)),"")} -> 15353.902 | N13: {=IFERROR(SUMPRODUCT($AA$2:$AA$2336,--(Healthcare!$J$2:$J$2336=$K13),--(Healthcare!$K$2:$K$2336=N$9),Healthcare!$M$2:$M$2336)/SUMPRODUCT($AA$2:$AA$2336,--(Healthcare!$J$2:$J$2336=$K13),--(Healthcare!$K$2:$K$2336=N$9)),"")} -> 19347.657 | P13: ='Healthcare Analysis'!A46 -> R1014 | Q13: {=IFERROR(SUMPRODUCT($AA$2:$AA$2336,--(Healthcare!$P$2:$P$2336=$P13),--(Healthcare!$N$2:$N$2336=Q$9),Healthcare!$M$2:$M$2336)/SUMPRODUCT($AA$2:$AA$2336,--(Healthcare!$P$2:$P$2336=$P13),--(Healthcare!$N$2:$N$2336=Q$9)),"")} -> 13891.86 | R13: {=IFERROR(SUMPRODUCT($AA$2:$AA$2336,--(Healthcare!$P$2:$P$2336=$P13),--(Healthcare!$N$2:$N$2336=R$9),Healthcare!$M$2:$M$2336)/SUMPRODUCT($AA$2:$AA$2336,--(Healthcare!$P$2:$P$2336=$P13),--(Healthcare!$N$2:$N$2336=R$9)),"")} -> 2395.17 | S13: {=IFERROR(SUMPRODUCT($AA$2:$AA$2336,--(Healthcare!$P$2:$P$2336=$P13),--(Healthcare!$N$2:$N$2336=S$9),Healthcare!$M$2:$M$2336)/SUMPRODUCT($AA$2:$AA$2336,--(Healthcare!$P$2:$P$2336=$P13),--(Healthcare!$N$2:$N$2336=S$9)),"")} -> 16950.485 | AA13: =SUBTOTAL(103,Healthcare!A13) -> 1 | AB13: =IF($AA13=1,Healthcare!Q13,NA()) -> 57 | AC13: =IF($AA13=1,Healthcare!C13,NA()) -> 42.13 | AD13: =IF($AA13=1,Healthcare!D13,NA()) -> 11.9 | AE13: =IF($AA13=1,Healthcare!M13,NA()) -> 48675.52 | AF13: =AB13 -> 57 | AG13: =AC13 -> 42.13 | AH13: =AB13 -> 57 | AI13: =AD13 -> 11.9 | AJ13: =AB13 -> 57 | AK13: =AE13 -> 48675.52
P14: ='Healthcare Analysis'!A47 -> R1015 | Q14: {=IFERROR(SUMPRODUCT($AA$2:$AA$2336,--(Healthcare!$P$2:$P$2336=$P14),--(Healthcare!$N$2:$N$2336=Q$9),Healthcare!$M$2:$M$2336)/SUMPRODUCT($AA$2:$AA$2336,--(Healthcare!$P$2:$P$2336=$P14),--(Healthcare!$N$2:$N$2336=Q$9)),"")} -> 21523.52 | R14: {=IFERROR(SUMPRODUCT($AA$2:$AA$2336,--(Healthcare!$P$2:$P$2336=$P14),--(Healthcare!$N$2:$N$2336=R$9),Healthcare!$M$2:$M$2336)/SUMPRODUCT($AA$2:$AA$2336,--(Healthcare!$P$2:$P$2336=$P14),--(Healthcare!$N$2:$N$2336=R$9)),"")} -> 15675.543 | S14: {=IFERROR(SUMPRODUCT($AA$2:$AA$2336,--(Healthcare!$P$2:$P$2336=$P14),--(Healthcare!$N$2:$N$2336=S$9),Healthcare!$M$2:$M$2336)/SUMPRODUCT($AA$2:$AA$2336,--(Healthcare!$P$2:$P$2336=$P14),--(Healthcare!$N$2:$N$2336=S$9)),"")} -> 7570.755 | AA14: =SUBTOTAL(103,Healthcare!A14) -> 1 | AB14: =IF($AA14=1,Healthcare!Q14,NA()) -> 60 | AC14: =IF($AA14=1,Healthcare!C14,NA()) -> 40.92 | AD14: =IF($AA14=1,Healthcare!D14,NA()) -> 8.41 | AE14: =IF($AA14=1,Healthcare!M14,NA()) -> 48673.56 | AF14: =AB14 -> 60 | AG14: =AC14 -> 40.92 | AH14: =AB14 -> 60 | AI14: =AD14 -> 8.41 | AJ14: =AB14 -> 60 | AK14: =AE14 -> 48673.56
P15: ='Healthcare Analysis'!A48 -> R1016 | Q15: {=IFERROR(SUMPRODUCT($AA$2:$AA$2336,--(Healthcare!$P$2:$P$2336=$P15),--(Healthcare!$N$2:$N$2336=Q$9),Healthcare!$M$2:$M$2336)/SUMPRODUCT($AA$2:$AA$2336,--(Healthcare!$P$2:$P$2336=$P15),--(Healthcare!$N$2:$N$2336=Q$9)),"")} -> 39868.616 | R15: {=IFERROR(SUMPRODUCT($AA$2:$AA$2336,--(Healthcare!$P$2:$P$2336=$P15),--(Healthcare!$N$2:$N$2336=R$9),Healthcare!$M$2:$M$2336)/SUMPRODUCT($AA$2:$AA$2336,--(Healthcare!$P$2:$P$2336=$P15),--(Healthcare!$N$2:$N$2336=R$9)),"")} -> 16075.963 | S15: {=IFERROR(SUMPRODUCT($AA$2:$AA$2336,--(Healthcare!$P$2:$P$2336=$P15),--(Healthcare!$N$2:$N$2336=S$9),Healthcare!$M$2:$M$2336)/SUMPRODUCT($AA$2:$AA$2336,--(Healthcare!$P$2:$P$2336=$P15),--(Healthcare!$N$2:$N$2336=S$9)),"")} -> 8133.0084 | AA15: =SUBTOTAL(103,Healthcare!A15) -> 1 | AB15: =IF($AA15=1,Healthcare!Q15,NA()) -> 54 | AC15: =IF($AA15=1,Healthcare!C15,NA()) -> 40.565 | AD15: =IF($AA15=1,Healthcare!D15,NA()) -> 7.02 | AE15: =IF($AA15=1,Healthcare!M15,NA()) -> 48549.18 | AF15: =AB15 -> 54 | AG15: =AC15 -> 40.565 | AH15: =AB15 -> 54 | AI15: =AD15 -> 7.02 | AJ15: =AB15 -> 54 | AK15: =AE15 -> 48549.18
P16: ='Healthcare Analysis'!A49 -> R1017 | Q16: {=IFERROR(SUMPRODUCT($AA$2:$AA$2336,--(Healthcare!$P$2:$P$2336=$P16),--(Healthcare!$N$2:$N$2336=Q$9),Healthcare!$M$2:$M$2336)/SUMPRODUCT($AA$2:$AA$2336,--(Healthcare!$P$2:$P$2336=$P16),--(Healthcare!$N$2:$N$2336=Q$9)),"")} -> 34070.596 | R16: {=IFERROR(SUMPRODUCT($AA$2:$AA$2336,--(Healthcare!$P$2:$P$2336=$P16),--(Healthcare!$N$2:$N$2336=R$9),Healthcare!$M$2:$M$2336)/SUMPRODUCT($AA$2:$AA$2336,--(Healthcare!$P$2:$P$2336=$P16),--(Healthcare!$N$2:$N$2336=R$9)),"")} -> 11365.622 | S16: {=IFERROR(SUMPRODUCT($AA$2:$AA$2336,--(Healthcare!$P$2:$P$2336=$P16),--(Healthcare!$N$2:$N$2336=S$9),Healthcare!$M$2:$M$2336)/SUMPRODUCT($AA$2:$AA$2336,--(Healthcare!$P$2:$P$2336=$P16),--(Healthcare!$N$2:$N$2336=S$9)),"")} -> 8667.3662 | AA16: =SUBTOTAL(103,Healthcare!A16) -> 1 | AB16: =IF($AA16=1,Healthcare!Q16,NA()) -> 61 | AC16: =IF($AA16=1,Healthcare!C16,NA()) -> 36.385 | AD16: =IF($AA16=1,Healthcare!D16,NA()) -> 7.59 | AE16: =IF($AA16=1,Healthcare!M16,NA()) -> 48517.56 | AF16: =AB16 -> 61 | AG16: =AC16 -> 36.385 | AH16: =AB16 -> 61 | AI16: =AD16 -> 7.59 | AJ16: =AB16 -> 61 | AK16: =AE16 -> 48517.56
P17: ='Healthcare Analysis'!A50 -> R1018 | Q17: {=IFERROR(SUMPRODUCT($AA$2:$AA$2336,--(Healthcare!$P$2:$P$2336=$P17),--(Healthcare!$N$2:$N$2336=Q$9),Healthcare!$M$2:$M$2336)/SUMPRODUCT($AA$2:$AA$2336,--(Healthcare!$P$2:$P$2336=$P17),--(Healthcare!$N$2:$N$2336=Q$9)),"")} -> 33475.82 | R17: {=IFERROR(SUMPRODUCT($AA$2:$AA$2336,--(Healthcare!$P$2:$P$2336=$P17),--(Healthcare!$N$2:$N$2336=R$9),Healthcare!$M$2:$M$2336)/SUMPRODUCT($AA$2:$AA$2336,--(Healthcare!$P$2:$P$2336=$P17),--(Healthcare!$N$2:$N$2336=R$9)),"")} -> 10139.553 | S17: {=IFERROR(SUMPRODUCT($AA$2:$AA$2336,--(Healthcare!$P$2:$P$2336=$P17),--(Healthcare!$N$2:$N$2336=S$9),Healthcare!$M$2:$M$2336)/SUMPRODUCT($AA$2:$AA$2336,--(Healthcare!$P$2:$P$2336=$P17),--(Healthcare!$N$2:$N$2336=S$9)),"")} -> 12570.97 | AA17: =SUBTOTAL(103,Healthcare!A17) -> 1 | AB17: =IF($AA17=1,Healthcare!Q17,NA()) -> 60 | AC17: =IF($AA17=1,Healthcare!C17,NA()) -> 39.9 | AD17: =IF($AA17=1,Healthcare!D17,NA()) -> 11.32 | AE17: =IF($AA17=1,Healthcare!M17,NA()) -> 48173.36 | AF17: =AB17 -> 60 | AG17: =AC17 -> 39.9 | AH17: =AB17 -> 60 | AI17: =AD17 -> 11.32 | AJ17: =AB17 -> 60 | AK17: =AE17 -> 48173.36
P18: ='Healthcare Analysis'!A51 -> R1019 | Q18: {=IFERROR(SUMPRODUCT($AA$2:$AA$2336,--(Healthcare!$P$2:$P$2336=$P18),--(Healthcare!$N$2:$N$2336=Q$9),Healthcare!$M$2:$M$2336)/SUMPRODUCT($AA$2:$AA$2336,--(Healthcare!$P$2:$P$2336=$P18),--(Healthcare!$N$2:$N$2336=Q$9)),"")} -> 27621.61 | R18: {=IFERROR(SUMPRODUCT($AA$2:$AA$2336,--(Healthcare!$P$2:$P$2336=$P18),--(Healthcare!$N$2:$N$2336=R$9),Healthcare!$M$2:$M$2336)/SUMPRODUCT($AA$2:$AA$2336,--(Healthcare!$P$2:$P$2336=$P18),--(Healthcare!$N$2:$N$2336=R$9)),"")} -> 8116.72 | S18: {=IFERROR(SUMPRODUCT($AA$2:$AA$2336,--(Healthcare!$P$2:$P$2336=$P18),--(Healthcare!$N$2:$N$2336=S$9),Healthcare!$M$2:$M$2336)/SUMPRODUCT($AA$2:$AA$2336,--(Healthcare!$P$2:$P$2336=$P18),--(Healthcare!$N$2:$N$2336=S$9)),"")} -> 12706.976 | AA18: =SUBTOTAL(103,Healthcare!A18) -> 1 | AB18: =IF($AA18=1,Healthcare!Q18,NA()) -> 64 | AC18: =IF($AA18=1,Healthcare!C18,NA()) -> 33.8 | AD18: =IF($AA18=1,Healthcare!D18,NA()) -> 7.67 | AE18: =IF($AA18=1,Healthcare!M18,NA()) -> 47928.03 | AF18: =AB18 -> 64 | AG18: =AC18 -> 33.8 | AH18: =AB18 -> 64 | AI18: =AD18 -> 7.67 | AJ18: =AB18 -> 64 | AK18: =AE18 -> 47928.03
P19: ='Healthcare Analysis'!A52 -> R1020 | Q19: {=IFERROR(SUMPRODUCT($AA$2:$AA$2336,--(Healthcare!$P$2:$P$2336=$P19),--(Healthcare!$N$2:$N$2336=Q$9),Healthcare!$M$2:$M$2336)/SUMPRODUCT($AA$2:$AA$2336,--(Healthcare!$P$2:$P$2336=$P19),--(Healthcare!$N$2:$N$2336=Q$9)),"")} | R19: {=IFERROR(SUMPRODUCT($AA$2:$AA$2336,--(Healthcare!$P$2:$P$2336=$P19),--(Healthcare!$N$2:$N$2336=R$9),Healthcare!$M$2:$M$2336)/SUMPRODUCT($AA$2:$AA$2336,--(Healthcare!$P$2:$P$2336=$P19),--(Healthcare!$N$2:$N$2336=R$9)),"")} -> 6760.5433 | S19: {=IFERROR(SUMPRODUCT($AA$2:$AA$2336,--(Healthcare!$P$2:$P$2336=$P19),--(Healthcare!$N$2:$N$2336=S$9),Healthcare!$M$2:$M$2336)/SUMPRODUCT($AA$2:$AA$2336,--(Healthcare!$P$2:$P$2336=$P19),--(Healthcare!$N$2:$N$2336=S$9)),"")} -> 11716.453 | AA19: =SUBTOTAL(103,Healthcare!A19) -> 1 | AB19: =IF($AA19=1,Healthcare!Q19,NA()) -> 59 | AC19: =IF($AA19=1,Healthcare!C19,NA()) -> 36.765 | AD19: =IF($AA19=1,Healthcare!D19,NA()) -> 7.29 | AE19: =IF($AA19=1,Healthcare!M19,NA()) -> 47896.79 | AF19: =AB19 -> 59 | AG19: =AC19 -> 36.765 | AH19: =AB19 -> 59 | AI19: =AD19 -> 7.29 | AJ19: =AB19 -> 59 | AK19: =AE19 -> 47896.79
